Workbook

Sheet Trial Balance
A1: entry_date | B1: (Multiple Items)
A2: account_type | B2: (All)
A4: Row Labels | B4: Sum of debit | C4: Sum of credit
A5: Accounts Payable | B5: 7056.62 | C5: 19311.46
A6: Accounts Receivable | B6: 63871.59 | C6: 22553.89
A7: Bank Account - Operating | B7: 222553.89 | C7: 42077.79
A8: Cost of Goods Sold | B8: 17964.15 | C8: 0
A9: Depreciation Expense | B9: 731.72 | C9: 0
A10: Employer FICA Expense | B10: 1710.52 | C10: 0
A11: Federal Income Tax Withholding Payable | B11: 0 | C11: 7741.3
A12: FICA Payable (Social Security & Medicare) | B12: 0 | C12: 1710.52
A13: Less Accumulated Depreciation - Furniture & Fixtures | B13: 0 | C13: 265.18
A14: Less Accumulated Depreciation - Office Equipment | B14: 0 | C14: 234.35
A15: Less Accumulated Depreciation - Vehicles | B15: 0 | C15: 232.19
A16: Owner's Equity / Common Stock | B16: 0 | C16: 200000
... A21: Grand Total | B21: 357998.27 | C21: 357998.27

Sheet general_ledger
A1: entry_number | B1: entry_date | C1: description | D1: debit | E1: credit | F1: name | G1: account_type
A2: 1 | B2: 45292 | C2: Opening balance â€” owner's equity contribution | D2: 200000 | E2: 0 | F2: Bank Account - Operating | G2: asset
A3: 1 | B3: 45292 | C3: Opening balance â€” owner's equity contribution | D3: 0 | E3: 200000 | F3: Owner's Equity / Common Stock | G3: equity
A4: 2 | B4: 45293 | C4: Sales invoice issued | D4: 1847.6 | E4: 0 | F4: Accounts Receivable | G4: asset
A5: 2 | B5: 45293 | C5: Sales invoice issued | D5: 0 | E5: 1718.7 | F5: Sales Revenue | G5: revenue
A6: 2 | B6: 45293 | C6: Sales invoice issued | D6: 0 | E6: 128.9 | F6: Sales Tax Payable | G6: liability
A7: 3 | B7: 45293 | C7: Sales invoice issued | D7: 948.28 | E7: 0 | F7: Accounts Receivable | G7: asset
A8: 3 | B8: 45293 | C8: Sales invoice issued | D8: 0 | E8: 882.13 | F8: Sales Revenue | G8: revenue
A9: 3 | B9: 45293 | C9: Sales invoice issued | D9: 0 | E9: 66.15 | F9: Sales Tax Payable | G9: liability
A10: 4 | B10: 45294 | C10: Sales invoice issued | D10: 494.99 | E10: 0 | F10: Accounts Receivable | G10: asset
A11: 4 | B11: 45294 | C11: Sales invoice issued | D11: 0 | E11: 460.46 | F11: Sales Revenue | G11: revenue
A12: 4 | B12: 45294 | C12: Sales invoice issued | D12: 0 | E12: 34.53 | F12: Sales Tax Payable | G12: liability
A13: 5 | B13: 45295 | C13: Payroll processed | D13: 21454.79 | E13: 0 | F13: Salaries & Wages | G13: expense
... A17028: 6764 | B17028: 46022 | C17028: Depreciation â€” Security System | D17028: 0 | E17028: 43.85 | F17028: Less Accumulated Depreciation - Office Equipment | G17028: asset

Sheet Forecast
E1: Target | F1: Margin
D2: Best Case | E2: 0.3 | F2: =F3+(E2/10) -> 0.65557999
D3: Base Case | E3: 0 | F3: =AVERAGE(E38:AB38) -> 0.62557999
D4: Worst Case | E4: -0.3 | F4: =F3+(E4/10) -> 0.59557999
A6: Best Case | E6: Actual Budget | AC6: Forecast
B7: Account | E7: 45292 | F7: =EDATE(E$7,1) -> 45323 | G7: =EDATE(F$7,1) -> 45352 | H7: =EDATE(G$7,1) -> 45383 | I7: =EDATE(H$7,1) -> 45413 | J7: =EDATE(I$7,1) -> 45444 | K7: =EDATE(J$7,1) -> 45474 | L7: =EDATE(K$7,1) -> 45505 | M7: =EDATE(L$7,1) -> 45536 | ... AN7: =EDATE(AM$7,1) -> 46357
B8: Revenue
C9: Sales Revenue | E9: =SUMIFS( general_ledger!$E:$E, general_ledger!$F:$F,Forecast!$C9, general_ledger!$B:$B,">="&Forecast!E$7, general_ledger!$B:$B,"<"&EDATE(Forecast!E$7,1) ) -> 59415.49 | F9: =SUMIFS( general_ledger!$E:$E, general_ledger!$F:$F,Forecast!$C9, general_ledger!$B:$B,">="&Forecast!F$7, general_ledger!$B:$B,"<"&EDATE(Forecast!F$7,1) ) -> 68342.89 | G9: =SUMIFS( general_ledger!$E:$E, general_ledger!$F:$F,Forecast!$C9, general_ledger!$B:$B,">="&Forecast!G$7, general_ledger!$B:$B,"<"&EDATE(Forecast!G$7,1) ) -> 99595.54 | H9: =SUMIFS( general_ledger!$E:$E, general_ledger!$F:$F,Forecast!$C9, general_ledger!$B:$B,">="&Forecast!H$7, general_ledger!$B:$B,"<"&EDATE(Forecast!H$7,1) ) -> 95861.08 | I9: =SUMIFS( general_ledger!$E:$E, general_ledger!$F:$F,Forecast!$C9, general_ledger!$B:$B,">="&Forecast!I$7, general_ledger!$B:$B,"<"&EDATE(Forecast!I$7,1) ) -> 150362.92 | J9: =SUMIFS( general_ledger!$E:$E, general_ledger!$F:$F,Forecast!$C9, general_ledger!$B:$B,">="&Forecast!J$7, general_ledger!$B:$B,"<"&EDATE(Forecast!J$7,1) ) -> 142942.71 | K9: =SUMIFS( general_ledger!$E:$E, general_ledger!$F:$F,Forecast!$C9, general_ledger!$B:$B,">="&Forecast!K$7, general_ledger!$B:$B,"<"&EDATE(Forecast!K$7,1) ) -> 149964.53 | L9: =SUMIFS( general_ledger!$E:$E, general_ledger!$F:$F,Forecast!$C9, general_ledger!$B:$B,">="&Forecast!L$7, general_ledger!$B:$B,"<"&EDATE(Forecast!L$7,1) ) -> 134993.04 | ... AB9: =SUMIFS( general_ledger!$E:$E, general_ledger!$F:$F,Forecast!$C9, general_ledger!$B:$B,">="&Forecast!AB$7, general_ledger!$B:$B,"<"&EDATE(Forecast!AB$7,1) ) -> 511798.72 | AC9: =AC35*(1+$E$2) -> 435729.35 | AD9: =AD35*(1+$E$2) -> 414206.86 | AE9: =AE35*(1+$E$2) -> 455989.96 | AF9: =AF35*(1+$E$2) -> 494489.76 | AG9: =AG35*(1+$E$2) -> 590836.05 | AH9: =AH35*(1+$E$2) -> 587395.28 | AI9: =AI35*(1+$E$2) -> 511004.26 | AJ9: =AJ35*(1+$E$2) -> 488171.68 | ... AN9: =AN35*(1+$E$2) -> 674993.2
C10: Cost of Goods Sold | E10: =SUMIFS( general_ledger!$D:$D, general_ledger!$F:$F,Forecast!$C10, general_ledger!$B:$B,">="&Forecast!E$7, general_ledger!$B:$B,"<"&EDATE(Forecast!E$7,1) ) -> 17964.15 | F10: =SUMIFS( general_ledger!$D:$D, general_ledger!$F:$F,Forecast!$C10, general_ledger!$B:$B,">="&Forecast!F$7, general_ledger!$B:$B,"<"&EDATE(Forecast!F$7,1) ) -> 10317.94 | G10: =SUMIFS( general_ledger!$D:$D, general_ledger!$F:$F,Forecast!$C10, general_ledger!$B:$B,">="&Forecast!G$7, general_ledger!$B:$B,"<"&EDATE(Forecast!G$7,1) ) -> 28087.98 | H10: =SUMIFS( general_ledger!$D:$D, general_ledger!$F:$F,Forecast!$C10, general_ledger!$B:$B,">="&Forecast!H$7, general_ledger!$B:$B,"<"&EDATE(Forecast!H$7,1) ) -> 41028.11 | I10: =SUMIFS( general_ledger!$D:$D, general_ledger!$F:$F,Forecast!$C10, general_ledger!$B:$B,">="&Forecast!I$7, general_ledger!$B:$B,"<"&EDATE(Forecast!I$7,1) ) -> 56000.79 | J10: =SUMIFS( general_ledger!$D:$D, general_ledger!$F:$F,Forecast!$C10, general_ledger!$B:$B,">="&Forecast!J$7, general_ledger!$B:$B,"<"&EDATE(Forecast!J$7,1) ) -> 70351.5 | K10: =SUMIFS( general_ledger!$D:$D, general_ledger!$F:$F,Forecast!$C10, general_ledger!$B:$B,">="&Forecast!K$7, general_ledger!$B:$B,"<"&EDATE(Forecast!K$7,1) ) -> 53447.14 | L10: =SUMIFS( general_ledger!$D:$D, general_ledger!$F:$F,Forecast!$C10, general_ledger!$B:$B,">="&Forecast!L$7, general_ledger!$B:$B,"<"&EDATE(Forecast!L$7,1) ) -> 61886.94 | ... AB10: =SUMIFS( general_ledger!$D:$D, general_ledger!$F:$F,Forecast!$C10, general_ledger!$B:$B,">="&Forecast!AB$7, general_ledger!$B:$B,"<"&EDATE(Forecast!AB$7,1) ) -> 125511.47 | AC10: =AC9-AC11 -> 150073.9 | AD10: =AD9-AD11 -> 142661.13 | AE10: =AE9-AE11 -> 157052.07 | AF10: =AF9-AF11 -> 170312.17 | AG10: =AG9-AG11 -> 203495.76 | AH10: =AH9-AH11 -> 202310.69 | AI10: =AI9-AI11 -> 176000.09 | AJ10: =AJ9-AJ11 -> 168136.09 | ... AN10: =AN9-AN11 -> 232481.16
B11: Gross Profit | E11: =E9-E10 -> 41451.34 | F11: =F9-F10 -> 58024.95 | G11: =G9-G10 -> 71507.56 | H11: =H9-H10 -> 54832.97 | I11: =I9-I10 -> 94362.13 | J11: =J9-J10 -> 72591.21 | K11: =K9-K10 -> 96517.39 | L11: =L9-L10 -> 73106.1 | ... AB11: =AB9-AB10 -> 386287.25 | AC11: =AC9*AC12 -> 285655.44 | AD11: =AD9*AD12 -> 271545.73 | AE11: =AE9*AE12 -> 298937.9 | AF11: =AF9*AF12 -> 324177.59 | AG11: =AG9*AG12 -> 387340.29 | AH11: =AH9*AH12 -> 385084.6 | AI11: =AI9*AI12 -> 335004.17 | AJ11: =AJ9*AJ12 -> 320035.59 | ... AN11: =AN9*AN12 -> 442512.04
C12: Gross Profit Margin | E12: =E11/E9 -> 0.69765208 | F12: =F11/F9 -> 0.84902687 | G12: =G11/G9 -> 0.71797954 | H12: =H11/H9 -> 0.57200451 | I12: =I11/I9 -> 0.6275625 | J12: =J11/J9 -> 0.50783429 | K12: =K11/K9 -> 0.64360146 | L12: =L11/L9 -> 0.54155459 | ... AB12: =AB11/AB9 -> 0.754764 | AC12: =$F$2 -> 0.65557999 | AD12: =$F$2 -> 0.65557999 | AE12: =$F$2 -> 0.65557999 | AF12: =$F$2 -> 0.65557999 | AG12: =$F$2 -> 0.65557999 | AH12: =$F$2 -> 0.65557999 | AI12: =$F$2 -> 0.65557999 | AJ12: =$F$2 -> 0.65557999 | ... AN12: =$F$2 -> 0.65557999
B14: Operating Expense
C15: Depreciation Expense
D16: Depreciation â€” Counter & Checkout | E16: =SUMIFS( general_ledger!$D:$D, general_ledger!$C:$C,Forecast!$D16, general_ledger!$B:$B,">="&Forecast!E$7, general_ledger!$B:$B,"<"&EDATE(Forecast!E$7,1) ) -> 48.28 | F16: =SUMIFS( general_ledger!$D:$D, general_ledger!$C:$C,Forecast!$D16, general_ledger!$B:$B,">="&Forecast!F$7, general_ledger!$B:$B,"<"&EDATE(Forecast!F$7,1) ) -> 48.28 | G16: =SUMIFS( general_ledger!$D:$D, general_ledger!$C:$C,Forecast!$D16, general_ledger!$B:$B,">="&Forecast!G$7, general_ledger!$B:$B,"<"&EDATE(Forecast!G$7,1) ) -> 48.28 | H16: =SUMIFS( general_ledger!$D:$D, general_ledger!$C:$C,Forecast!$D16, general_ledger!$B:$B,">="&Forecast!H$7, general_ledger!$B:$B,"<"&EDATE(Forecast!H$7,1) ) -> 48.28 | I16: =SUMIFS( general_ledger!$D:$D, general_ledger!$C:$C,Forecast!$D16, general_ledger!$B:$B,">="&Forecast!I$7, general_ledger!$B:$B,"<"&EDATE(Forecast!I$7,1) ) -> 48.28 | J16: =SUMIFS( general_ledger!$D:$D, general_ledger!$C:$C,Forecast!$D16, general_ledger!$B:$B,">="&Forecast!J$7, general_ledger!$B:$B,"<"&EDATE(Forecast!J$7,1) ) -> 48.28 | K16: =SUMIFS( general_ledger!$D:$D, general_ledger!$C:$C,Forecast!$D16, general_ledger!$B:$B,">="&Forecast!K$7, general_ledger!$B:$B,"<"&EDATE(Forecast!K$7,1) ) -> 48.28 | L16: =SUMIFS( general_ledger!$D:$D, general_ledger!$C:$C,Forecast!$D16, general_ledger!$B:$B,">="&Forecast!L$7, general_ledger!$B:$B,"<"&EDATE(Forecast!L$7,1) ) -> 48.28 | ... AB16: =SUMIFS( general_ledger!$D:$D, general_ledger!$C:$C,Forecast!$D16, general_ledger!$B:$B,">="&Forecast!AB$7, general_ledger!$B:$B,"<"&EDATE(Forecast!AB$7,1) ) -> 48.28
D17: Depreciation â€” Delivery Van | E17: =SUMIFS( general_ledger!$D:$D, general_ledger!$C:$C,Forecast!$D17, general_ledger!$B:$B,">="&Forecast!E$7, general_ledger!$B:$B,"<"&EDATE(Forecast!E$7,1) ) -> 232.19 | F17: =SUMIFS( general_ledger!$D:$D, general_ledger!$C:$C,Forecast!$D17, general_ledger!$B:$B,">="&Forecast!F$7, general_ledger!$B:$B,"<"&EDATE(Forecast!F$7,1) ) -> 232.19 | G17: =SUMIFS( general_ledger!$D:$D, general_ledger!$C:$C,Forecast!$D17, general_ledger!$B:$B,">="&Forecast!G$7, general_ledger!$B:$B,"<"&EDATE(Forecast!G$7,1) ) -> 232.19 | H17: =SUMIFS( general_ledger!$D:$D, general_ledger!$C:$C,Forecast!$D17, general_ledger!$B:$B,">="&Forecast!H$7, general_ledger!$B:$B,"<"&EDATE(Forecast!H$7,1) ) -> 232.19 | I17: =SUMIFS( general_ledger!$D:$D, general_ledger!$C:$C,Forecast!$D17, general_ledger!$B:$B,">="&Forecast!I$7, general_ledger!$B:$B,"<"&EDATE(Forecast!I$7,1) ) -> 232.19 | J17: =SUMIFS( general_ledger!$D:$D, general_ledger!$C:$C,Forecast!$D17, general_ledger!$B:$B,">="&Forecast!J$7, general_ledger!$B:$B,"<"&EDATE(Forecast!J$7,1) ) -> 232.19 | K17: =SUMIFS( general_ledger!$D:$D, general_ledger!$C:$C,Forecast!$D17, general_ledger!$B:$B,">="&Forecast!K$7, general_ledger!$B:$B,"<"&EDATE(Forecast!K$7,1) ) -> 232.19 | L17: =SUMIFS( general_ledger!$D:$D, general_ledger!$C:$C,Forecast!$D17, general_ledger!$B:$B,">="&Forecast!L$7, general_ledger!$B:$B,"<"&EDATE(Forecast!L$7,1) ) -> 232.19 | ... AB17: =SUMIFS( general_ledger!$D:$D, general_ledger!$C:$C,Forecast!$D17, general_ledger!$B:$B,">="&Forecast!AB$7, general_ledger!$B:$B,"<"&EDATE(Forecast!AB$7,1) ) -> 232.19
D18: Depreciation â€” Display Stands | E18: =SUMIFS( general_ledger!$D:$D, general_ledger!$C:$C,Forecast!$D18, general_ledger!$B:$B,">="&Forecast!E$7, general_ledger!$B:$B,"<"&EDATE(Forecast!E$7,1) ) -> 76.8 | F18: =SUMIFS( general_ledger!$D:$D, general_ledger!$C:$C,Forecast!$D18, general_ledger!$B:$B,">="&Forecast!F$7, general_ledger!$B:$B,"<"&EDATE(Forecast!F$7,1) ) -> 76.8 | G18: =SUMIFS( general_ledger!$D:$D, general_ledger!$C:$C,Forecast!$D18, general_ledger!$B:$B,">="&Forecast!G$7, general_ledger!$B:$B,"<"&EDATE(Forecast!G$7,1) ) -> 76.8 | H18: =SUMIFS( general_ledger!$D:$D, general_ledger!$C:$C,Forecast!$D18, general_ledger!$B:$B,">="&Forecast!H$7, general_ledger!$B:$B,"<"&EDATE(Forecast!H$7,1) ) -> 76.8 | I18: =SUMIFS( general_ledger!$D:$D, general_ledger!$C:$C,Forecast!$D18, general_ledger!$B:$B,">="&Forecast!I$7, general_ledger!$B:$B,"<"&EDATE(Forecast!I$7,1) ) -> 76.8 | J18: =SUMIFS( general_ledger!$D:$D, general_ledger!$C:$C,Forecast!$D18, general_ledger!$B:$B,">="&Forecast!J$7, general_ledger!$B:$B,"<"&EDATE(Forecast!J$7,1) ) -> 76.8 | K18: =SUMIFS( general_ledger!$D:$D, general_ledger!$C:$C,Forecast!$D18, general_ledger!$B:$B,">="&Forecast!K$7, general_ledger!$B:$B,"<"&EDATE(Forecast!K$7,1) ) -> 76.8 | L18: =SUMIFS( general_ledger!$D:$D, general_ledger!$C:$C,Forecast!$D18, general_ledger!$B:$B,">="&Forecast!L$7, general_ledger!$B:$B,"<"&EDATE(Forecast!L$7,1) ) -> 76.8 | ... AB18: =SUMIFS( general_ledger!$D:$D, general_ledger!$C:$C,Forecast!$D18, general_ledger!$B:$B,">="&Forecast!AB$7, general_ledger!$B:$B,"<"&EDATE(Forecast!AB$7,1) ) -> 76.8
D19: Depreciation â€” Laptop x2 | E19: =SUMIFS( general_ledger!$D:$D, general_ledger!$C:$C,Forecast!$D19, general_ledger!$B:$B,">="&Forecast!E$7, general_ledger!$B:$B,"<"&EDATE(Forecast!E$7,1) ) -> 76.86 | F19: =SUMIFS( general_ledger!$D:$D, general_ledger!$C:$C,Forecast!$D19, general_ledger!$B:$B,">="&Forecast!F$7, general_ledger!$B:$B,"<"&EDATE(Forecast!F$7,1) ) -> 76.86 | G19: =SUMIFS( general_ledger!$D:$D, general_ledger!$C:$C,Forecast!$D19, general_ledger!$B:$B,">="&Forecast!G$7, general_ledger!$B:$B,"<"&EDATE(Forecast!G$7,1) ) -> 76.86 | H19: =SUMIFS( general_ledger!$D:$D, general_ledger!$C:$C,Forecast!$D19, general_ledger!$B:$B,">="&Forecast!H$7, general_ledger!$B:$B,"<"&EDATE(Forecast!H$7,1) ) -> 76.86 | I19: =SUMIFS( general_ledger!$D:$D, general_ledger!$C:$C,Forecast!$D19, general_ledger!$B:$B,">="&Forecast!I$7, general_ledger!$B:$B,"<"&EDATE(Forecast!I$7,1) ) -> 76.86 | J19: =SUMIFS( general_ledger!$D:$D, general_ledger!$C:$C,Forecast!$D19, general_ledger!$B:$B,">="&Forecast!J$7, general_ledger!$B:$B,"<"&EDATE(Forecast!J$7,1) ) -> 76.86 | K19: =SUMIFS( general_ledger!$D:$D, general_ledger!$C:$C,Forecast!$D19, general_ledger!$B:$B,">="&Forecast!K$7, general_ledger!$B:$B,"<"&EDATE(Forecast!K$7,1) ) -> 76.86 | L19: =SUMIFS( general_ledger!$D:$D, general_ledger!$C:$C,Forecast!$D19, general_ledger!$B:$B,">="&Forecast!L$7, general_ledger!$B:$B,"<"&EDATE(Forecast!L$7,1) ) -> 76.86 | ... AB19: =SUMIFS( general_ledger!$D:$D, general_ledger!$C:$C,Forecast!$D19, general_ledger!$B:$B,">="&Forecast!AB$7, general_ledger!$B:$B,"<"&EDATE(Forecast!AB$7,1) ) -> 0
D20: Depreciation â€” POS System | E20: =SUMIFS( general_ledger!$D:$D, general_ledger!$C:$C,Forecast!$D20, general_ledger!$B:$B,">="&Forecast!E$7, general_ledger!$B:$B,"<"&EDATE(Forecast!E$7,1) ) -> 93.61 | F20: =SUMIFS( general_ledger!$D:$D, general_ledger!$C:$C,Forecast!$D20, general_ledger!$B:$B,">="&Forecast!F$7, general_ledger!$B:$B,"<"&EDATE(Forecast!F$7,1) ) -> 93.61 | G20: =SUMIFS( general_ledger!$D:$D, general_ledger!$C:$C,Forecast!$D20, general_ledger!$B:$B,">="&Forecast!G$7, general_ledger!$B:$B,"<"&EDATE(Forecast!G$7,1) ) -> 93.61 | H20: =SUMIFS( general_ledger!$D:$D, general_ledger!$C:$C,Forecast!$D20, general_ledger!$B:$B,">="&Forecast!H$7, general_ledger!$B:$B,"<"&EDATE(Forecast!H$7,1) ) -> 93.61 | I20: =SUMIFS( general_ledger!$D:$D, general_ledger!$C:$C,Forecast!$D20, general_ledger!$B:$B,">="&Forecast!I$7, general_ledger!$B:$B,"<"&EDATE(Forecast!I$7,1) ) -> 93.61 | J20: =SUMIFS( general_ledger!$D:$D, general_ledger!$C:$C,Forecast!$D20, general_ledger!$B:$B,">="&Forecast!J$7, general_ledger!$B:$B,"<"&EDATE(Forecast!J$7,1) ) -> 93.61 | K20: =SUMIFS( general_ledger!$D:$D, general_ledger!$C:$C,Forecast!$D20, general_ledger!$B:$B,">="&Forecast!K$7, general_ledger!$B:$B,"<"&EDATE(Forecast!K$7,1) ) -> 93.61 | L20: =SUMIFS( general_ledger!$D:$D, general_ledger!$C:$C,Forecast!$D20, general_ledger!$B:$B,">="&Forecast!L$7, general_ledger!$B:$B,"<"&EDATE(Forecast!L$7,1) ) -> 93.61 | ... AB20: =SUMIFS( general_ledger!$D:$D, general_ledger!$C:$C,Forecast!$D20, general_ledger!$B:$B,">="&Forecast!AB$7, general_ledger!$B:$B,"<"&EDATE(Forecast!AB$7,1) ) -> 0
D21: Depreciation â€” Printer/Scanner | E21: =SUMIFS( general_ledger!$D:$D, general_ledger!$C:$C,Forecast!$D21, general_ledger!$B:$B,">="&Forecast!E$7, general_ledger!$B:$B,"<"&EDATE(Forecast!E$7,1) ) -> 20.03 | F21: =SUMIFS( general_ledger!$D:$D, general_ledger!$C:$C,Forecast!$D21, general_ledger!$B:$B,">="&Forecast!F$7, general_ledger!$B:$B,"<"&EDATE(Forecast!F$7,1) ) -> 20.03 | G21: =SUMIFS( general_ledger!$D:$D, general_ledger!$C:$C,Forecast!$D21, general_ledger!$B:$B,">="&Forecast!G$7, general_ledger!$B:$B,"<"&EDATE(Forecast!G$7,1) ) -> 20.03 | H21: =SUMIFS( general_ledger!$D:$D, general_ledger!$C:$C,Forecast!$D21, general_ledger!$B:$B,">="&Forecast!H$7, general_ledger!$B:$B,"<"&EDATE(Forecast!H$7,1) ) -> 20.03 | I21: =SUMIFS( general_ledger!$D:$D, general_ledger!$C:$C,Forecast!$D21, general_ledger!$B:$B,">="&Forecast!I$7, general_ledger!$B:$B,"<"&EDATE(Forecast!I$7,1) ) -> 20.03 | J21: =SUMIFS( general_ledger!$D:$D, general_ledger!$C:$C,Forecast!$D21, general_ledger!$B:$B,">="&Forecast!J$7, general_ledger!$B:$B,"<"&EDATE(Forecast!J$7,1) ) -> 20.03 | K21: =SUMIFS( general_ledger!$D:$D, general_ledger!$C:$C,Forecast!$D21, general_ledger!$B:$B,">="&Forecast!K$7, general_ledger!$B:$B,"<"&EDATE(Forecast!K$7,1) ) -> 20.03 | L21: =SUMIFS( general_ledger!$D:$D, general_ledger!$C:$C,Forecast!$D21, general_ledger!$B:$B,">="&Forecast!L$7, general_ledger!$B:$B,"<"&EDATE(Forecast!L$7,1) ) -> 20.03 | ... AB21: =SUMIFS( general_ledger!$D:$D, general_ledger!$C:$C,Forecast!$D21, general_ledger!$B:$B,">="&Forecast!AB$7, general_ledger!$B:$B,"<"&EDATE(Forecast!AB$7,1) ) -> 20.03
D22: Depreciation â€” Security System | E22: =SUMIFS( general_ledger!$D:$D, general_ledger!$C:$C,Forecast!$D22, general_ledger!$B:$B,">="&Forecast!E$7, general_ledger!$B:$B,"<"&EDATE(Forecast!E$7,1) ) -> 43.85 | F22: =SUMIFS( general_ledger!$D:$D, general_ledger!$C:$C,Forecast!$D22, general_ledger!$B:$B,">="&Forecast!F$7, general_ledger!$B:$B,"<"&EDATE(Forecast!F$7,1) ) -> 43.85 | G22: =SUMIFS( general_ledger!$D:$D, general_ledger!$C:$C,Forecast!$D22, general_ledger!$B:$B,">="&Forecast!G$7, general_ledger!$B:$B,"<"&EDATE(Forecast!G$7,1) ) -> 43.85 | H22: =SUMIFS( general_ledger!$D:$D, general_ledger!$C:$C,Forecast!$D22, general_ledger!$B:$B,">="&Forecast!H$7, general_ledger!$B:$B,"<"&EDATE(Forecast!H$7,1) ) -> 43.85 | I22: =SUMIFS( general_ledger!$D:$D, general_ledger!$C:$C,Forecast!$D22, general_ledger!$B:$B,">="&Forecast!I$7, general_ledger!$B:$B,"<"&EDATE(Forecast!I$7,1) ) -> 43.85 | J22: =SUMIFS( general_ledger!$D:$D, general_ledger!$C:$C,Forecast!$D22, general_ledger!$B:$B,">="&Forecast!J$7, general_ledger!$B:$B,"<"&EDATE(Forecast!J$7,1) ) -> 43.85 | K22: =SUMIFS( general_ledger!$D:$D, general_ledger!$C:$C,Forecast!$D22, general_ledger!$B:$B,">="&Forecast!K$7, general_ledger!$B:$B,"<"&EDATE(Forecast!K$7,1) ) -> 43.85 | L22: =SUMIFS( general_ledger!$D:$D, general_ledger!$C:$C,Forecast!$D22, general_ledger!$B:$B,">="&Forecast!L$7, general_ledger!$B:$B,"<"&EDATE(Forecast!L$7,1) ) -> 43.85 | ... AB22: =SUMIFS( general_ledger!$D:$D, general_ledger!$C:$C,Forecast!$D22, general_ledger!$B:$B,">="&Forecast!AB$7, general_ledger!$B:$B,"<"&EDATE(Forecast!AB$7,1) ) -> 43.85
D23: Depreciation â€” Shop Shelving | E23: =SUMIFS( general_ledger!$D:$D, general_ledger!$C:$C,Forecast!$D23, general_ledger!$B:$B,">="&Forecast!E$7, general_ledger!$B:$B,"<"&EDATE(Forecast!E$7,1) ) -> 86.89 | F23: =SUMIFS( general_ledger!$D:$D, general_ledger!$C:$C,Forecast!$D23, general_ledger!$B:$B,">="&Forecast!F$7, general_ledger!$B:$B,"<"&EDATE(Forecast!F$7,1) ) -> 86.89 | G23: =SUMIFS( general_ledger!$D:$D, general_ledger!$C:$C,Forecast!$D23, general_ledger!$B:$B,">="&Forecast!G$7, general_ledger!$B:$B,"<"&EDATE(Forecast!G$7,1) ) -> 86.89 | H23: =SUMIFS( general_ledger!$D:$D, general_ledger!$C:$C,Forecast!$D23, general_ledger!$B:$B,">="&Forecast!H$7, general_ledger!$B:$B,"<"&EDATE(Forecast!H$7,1) ) -> 86.89 | I23: =SUMIFS( general_ledger!$D:$D, general_ledger!$C:$C,Forecast!$D23, general_ledger!$B:$B,">="&Forecast!I$7, general_ledger!$B:$B,"<"&EDATE(Forecast!I$7,1) ) -> 86.89 | J23: =SUMIFS( general_ledger!$D:$D, general_ledger!$C:$C,Forecast!$D23, general_ledger!$B:$B,">="&Forecast!J$7, general_ledger!$B:$B,"<"&EDATE(Forecast!J$7,1) ) -> 86.89 | K23: =SUMIFS( general_ledger!$D:$D, general_ledger!$C:$C,Forecast!$D23, general_ledger!$B:$B,">="&Forecast!K$7, general_ledger!$B:$B,"<"&EDATE(Forecast!K$7,1) ) -> 86.89 | L23: =SUMIFS( general_ledger!$D:$D, general_ledger!$C:$C,Forecast!$D23, general_ledger!$B:$B,">="&Forecast!L$7, general_ledger!$B:$B,"<"&EDATE(Forecast!L$7,1) ) -> 86.89 | ... AB23: =SUMIFS( general_ledger!$D:$D, general_ledger!$C:$C,Forecast!$D23, general_ledger!$B:$B,">="&Forecast!AB$7, general_ledger!$B:$B,"<"&EDATE(Forecast!AB$7,1) ) -> 86.89
D24: Depreciation â€” Signage | E24: =SUMIFS( general_ledger!$D:$D, general_ledger!$C:$C,Forecast!$D24, general_ledger!$B:$B,">="&Forecast!E$7, general_ledger!$B:$B,"<"&EDATE(Forecast!E$7,1) ) -> 53.21 | F24: =SUMIFS( general_ledger!$D:$D, general_ledger!$C:$C,Forecast!$D24, general_ledger!$B:$B,">="&Forecast!F$7, general_ledger!$B:$B,"<"&EDATE(Forecast!F$7,1) ) -> 53.21 | G24: =SUMIFS( general_ledger!$D:$D, general_ledger!$C:$C,Forecast!$D24, general_ledger!$B:$B,">="&Forecast!G$7, general_ledger!$B:$B,"<"&EDATE(Forecast!G$7,1) ) -> 53.21 | H24: =SUMIFS( general_ledger!$D:$D, general_ledger!$C:$C,Forecast!$D24, general_ledger!$B:$B,">="&Forecast!H$7, general_ledger!$B:$B,"<"&EDATE(Forecast!H$7,1) ) -> 53.21 | I24: =SUMIFS( general_ledger!$D:$D, general_ledger!$C:$C,Forecast!$D24, general_ledger!$B:$B,">="&Forecast!I$7, general_ledger!$B:$B,"<"&EDATE(Forecast!I$7,1) ) -> 53.21 | J24: =SUMIFS( general_ledger!$D:$D, general_ledger!$C:$C,Forecast!$D24, general_ledger!$B:$B,">="&Forecast!J$7, general_ledger!$B:$B,"<"&EDATE(Forecast!J$7,1) ) -> 53.21 | K24: =SUMIFS( general_ledger!$D:$D, general_ledger!$C:$C,Forecast!$D24, general_ledger!$B:$B,">="&Forecast!K$7, general_ledger!$B:$B,"<"&EDATE(Forecast!K$7,1) ) -> 53.21 | L24: =SUMIFS( general_ledger!$D:$D, general_ledger!$C:$C,Forecast!$D24, general_ledger!$B:$B,">="&Forecast!L$7, general_ledger!$B:$B,"<"&EDATE(Forecast!L$7,1) ) -> 53.21 | ... AB24: =SUMIFS( general_ledger!$D:$D, general_ledger!$C:$C,Forecast!$D24, general_ledger!$B:$B,">="&Forecast!AB$7, general_ledger!$B:$B,"<"&EDATE(Forecast!AB$7,1) ) -> 53.21
C25: Depreciation Expense | E25: =SUMIFS( general_ledger!$D:$D, general_ledger!$F:$F,Forecast!$C25, general_ledger!$B:$B,">="&Forecast!E$7, general_ledger!$B:$B,"<"&EDATE(Forecast!E$7,1) ) -> 731.72 | F25: =SUMIFS( general_ledger!$D:$D, general_ledger!$F:$F,Forecast!$C25, general_ledger!$B:$B,">="&Forecast!F$7, general_ledger!$B:$B,"<"&EDATE(Forecast!F$7,1) ) -> 731.72 | G25: =SUMIFS( general_ledger!$D:$D, general_ledger!$F:$F,Forecast!$C25, general_ledger!$B:$B,">="&Forecast!G$7, general_ledger!$B:$B,"<"&EDATE(Forecast!G$7,1) ) -> 731.72 | H25: =SUMIFS( general_ledger!$D:$D, general_ledger!$F:$F,Forecast!$C25, general_ledger!$B:$B,">="&Forecast!H$7, general_ledger!$B:$B,"<"&EDATE(Forecast!H$7,1) ) -> 731.72 | I25: =SUMIFS( general_ledger!$D:$D, general_ledger!$F:$F,Forecast!$C25, general_ledger!$B:$B,">="&Forecast!I$7, general_ledger!$B:$B,"<"&EDATE(Forecast!I$7,1) ) -> 731.72 | J25: =SUMIFS( general_ledger!$D:$D, general_ledger!$F:$F,Forecast!$C25, general_ledger!$B:$B,">="&Forecast!J$7, general_ledger!$B:$B,"<"&EDATE(Forecast!J$7,1) ) -> 731.72 | K25: =SUMIFS( general_ledger!$D:$D, general_ledger!$F:$F,Forecast!$C25, general_ledger!$B:$B,">="&Forecast!K$7, general_ledger!$B:$B,"<"&EDATE(Forecast!K$7,1) ) -> 731.72 | L25: =SUMIFS( general_ledger!$D:$D, general_ledger!$F:$F,Forecast!$C25, general_ledger!$B:$B,">="&Forecast!L$7, general_ledger!$B:$B,"<"&EDATE(Forecast!L$7,1) ) -> 731.72 | ... AB25: =SUMIFS( general_ledger!$D:$D, general_ledger!$F:$F,Forecast!$C25, general_ledger!$B:$B,">="&Forecast!AB$7, general_ledger!$B:$B,"<"&EDATE(Forecast!AB$7,1) ) -> 561.25 | AC25: =_xlfn.FORECAST.ETS(AC$7,$E25:AB25,$E$7:AB$7,) -> 631.20712 | AD25: =_xlfn.FORECAST.ETS(AD$7,$E25:AC25,$E$7:AC$7,) -> 626.09166 | AE25: =_xlfn.FORECAST.ETS(AE$7,$E25:AD25,$E$7:AD$7,) -> 638.52424 | AF25: =_xlfn.FORECAST.ETS(AF$7,$E25:AE25,$E$7:AE$7,) -> 633.70924 | AG25: =_xlfn.FORECAST.ETS(AG$7,$E25:AF25,$E$7:AF$7,) -> 631.52456 | AH25: =_xlfn.FORECAST.ETS(AH$7,$E25:AG25,$E$7:AG$7,) -> 626.89233 | AI25: =_xlfn.FORECAST.ETS(AI$7,$E25:AH25,$E$7:AH$7,) -> 622.28321 | AJ25: =_xlfn.FORECAST.ETS(AJ$7,$E25:AI25,$E$7:AI$7,) -> 617.6943 | ... AN25: =_xlfn.FORECAST.ETS(AN$7,$E25:AM25,$E$7:AM$7,) -> 596.71328
C27: Salaries & Wages | E27: =SUMIFS( general_ledger!$D:$D, general_ledger!$F:$F,Forecast!$C27, general_ledger!$B:$B,">="&Forecast!E$7, general_ledger!$B:$B,"<"&EDATE(Forecast!E$7,1) ) -> 42762.47 | F27: =SUMIFS( general_ledger!$D:$D, general_ledger!$F:$F,Forecast!$C27, general_ledger!$B:$B,">="&Forecast!F$7, general_ledger!$B:$B,"<"&EDATE(Forecast!F$7,1) ) -> 64085.27 | G27: =SUMIFS( general_ledger!$D:$D, general_ledger!$F:$F,Forecast!$C27, general_ledger!$B:$B,">="&Forecast!G$7, general_ledger!$B:$B,"<"&EDATE(Forecast!G$7,1) ) -> 42810.03 | H27: =SUMIFS( general_ledger!$D:$D, general_ledger!$F:$F,Forecast!$C27, general_ledger!$B:$B,">="&Forecast!H$7, general_ledger!$B:$B,"<"&EDATE(Forecast!H$7,1) ) -> 42842.48 | I27: =SUMIFS( general_ledger!$D:$D, general_ledger!$F:$F,Forecast!$C27, general_ledger!$B:$B,">="&Forecast!I$7, general_ledger!$B:$B,"<"&EDATE(Forecast!I$7,1) ) -> 42615.36 | J27: =SUMIFS( general_ledger!$D:$D, general_ledger!$F:$F,Forecast!$C27, general_ledger!$B:$B,">="&Forecast!J$7, general_ledger!$B:$B,"<"&EDATE(Forecast!J$7,1) ) -> 42892.32 | K27: =SUMIFS( general_ledger!$D:$D, general_ledger!$F:$F,Forecast!$C27, general_ledger!$B:$B,">="&Forecast!K$7, general_ledger!$B:$B,"<"&EDATE(Forecast!K$7,1) ) -> 44351.63 | L27: =SUMIFS( general_ledger!$D:$D, general_ledger!$F:$F,Forecast!$C27, general_ledger!$B:$B,">="&Forecast!L$7, general_ledger!$B:$B,"<"&EDATE(Forecast!L$7,1) ) -> 66220.55 | ... AB27: =SUMIFS( general_ledger!$D:$D, general_ledger!$F:$F,Forecast!$C27, general_ledger!$B:$B,">="&Forecast!AB$7, general_ledger!$B:$B,"<"&EDATE(Forecast!AB$7,1) ) -> 45133.72 | AC27: =_xlfn.FORECAST.ETS(AC$7,$E27:AB27,$E$7:AB$7,) -> 57488.795 | AD27: =_xlfn.FORECAST.ETS(AD$7,$E27:AC27,$E$7:AC$7,) -> 57099.005 | AE27: =_xlfn.FORECAST.ETS(AE$7,$E27:AD27,$E$7:AD$7,) -> 45969.371 | AF27: =_xlfn.FORECAST.ETS(AF$7,$E27:AE27,$E$7:AE$7,) -> 45166.126 | AG27: =_xlfn.FORECAST.ETS(AG$7,$E27:AF27,$E$7:AF$7,) -> 46323.232 | AH27: =_xlfn.FORECAST.ETS(AH$7,$E27:AG27,$E$7:AG$7,) -> 46057.589 | AI27: =_xlfn.FORECAST.ETS(AI$7,$E27:AH27,$E$7:AH$7,) -> 62702.267 | AJ27: =_xlfn.FORECAST.ETS(AJ$7,$E27:AI27,$E$7:AI$7,) -> 53883.189 | ... AN27: =_xlfn.FORECAST.ETS(AN$7,$E27:AM27,$E$7:AM$7,) -> 47627.914
C28: Employer FICA Expense | E28: =SUMIFS( general_ledger!$D:$D, general_ledger!$F:$F,Forecast!$C28, general_ledger!$B:$B,">="&Forecast!E$7, general_ledger!$B:$B,"<"&EDATE(Forecast!E$7,1) ) -> 1710.52 | F28: =SUMIFS( general_ledger!$D:$D, general_ledger!$F:$F,Forecast!$C28, general_ledger!$B:$B,">="&Forecast!F$7, general_ledger!$B:$B,"<"&EDATE(Forecast!F$7,1) ) -> 2563.45 | G28: =SUMIFS( general_ledger!$D:$D, general_ledger!$F:$F,Forecast!$C28, general_ledger!$B:$B,">="&Forecast!G$7, general_ledger!$B:$B,"<"&EDATE(Forecast!G$7,1) ) -> 1712.43 | H28: =SUMIFS( general_ledger!$D:$D, general_ledger!$F:$F,Forecast!$C28, general_ledger!$B:$B,">="&Forecast!H$7, general_ledger!$B:$B,"<"&EDATE(Forecast!H$7,1) ) -> 1713.73 | I28: =SUMIFS( general_ledger!$D:$D, general_ledger!$F:$F,Forecast!$C28, general_ledger!$B:$B,">="&Forecast!I$7, general_ledger!$B:$B,"<"&EDATE(Forecast!I$7,1) ) -> 1704.64 | J28: =SUMIFS( general_ledger!$D:$D, general_ledger!$F:$F,Forecast!$C28, general_ledger!$B:$B,">="&Forecast!J$7, general_ledger!$B:$B,"<"&EDATE(Forecast!J$7,1) ) -> 1715.71 | K28: =SUMIFS( general_ledger!$D:$D, general_ledger!$F:$F,Forecast!$C28, general_ledger!$B:$B,">="&Forecast!K$7, general_ledger!$B:$B,"<"&EDATE(Forecast!K$7,1) ) -> 1774.06 | L28: =SUMIFS( general_ledger!$D:$D, general_ledger!$F:$F,Forecast!$C28, general_ledger!$B:$B,">="&Forecast!L$7, general_ledger!$B:$B,"<"&EDATE(Forecast!L$7,1) ) -> 2648.83 | ... AB28: =SUMIFS( general_ledger!$D:$D, general_ledger!$F:$F,Forecast!$C28, general_ledger!$B:$B,">="&Forecast!AB$7, general_ledger!$B:$B,"<"&EDATE(Forecast!AB$7,1) ) -> 1805.35 | AC28: =_xlfn.FORECAST.ETS(AC$7,$E28:AB28,$E$7:AB$7,) -> 2299.5403 | AD28: =_xlfn.FORECAST.ETS(AD$7,$E28:AC28,$E$7:AC$7,) -> 2283.9534 | AE28: =_xlfn.FORECAST.ETS(AE$7,$E28:AD28,$E$7:AD$7,) -> 1838.7699 | AF28: =_xlfn.FORECAST.ETS(AF$7,$E28:AE28,$E$7:AE$7,) -> 1806.6405 | AG28: =_xlfn.FORECAST.ETS(AG$7,$E28:AF28,$E$7:AF$7,) -> 1852.9209 | AH28: =_xlfn.FORECAST.ETS(AH$7,$E28:AG28,$E$7:AG$7,) -> 1842.2973 | AI28: =_xlfn.FORECAST.ETS(AI$7,$E28:AH28,$E$7:AH$7,) -> 2508.0793 | AJ28: =_xlfn.FORECAST.ETS(AJ$7,$E28:AI28,$E$7:AI$7,) -> 2155.3148 | ... AN28: =_xlfn.FORECAST.ETS(AN$7,$E28:AM28,$E$7:AM$7,) -> 1905.1041
B29: Toal Operating Expense | E29: =SUM(E25,E27:E28) -> 45204.71 | F29: =SUM(F25,F27:F28) -> 67380.44 | G29: =SUM(G25,G27:G28) -> 45254.18 | H29: =SUM(H25,H27:H28) -> 45287.93 | I29: =SUM(I25,I27:I28) -> 45051.72 | J29: =SUM(J25,J27:J28) -> 45339.75 | K29: =SUM(K25,K27:K28) -> 46857.41 | L29: =SUM(L25,L27:L28) -> 69601.1 | ... AN29: =SUM(AN25,AN27:AN28) -> 50129.732
B30: Operating Profit | E30: =E11-E29 -> -3753.37 | F30: =F11-F29 -> -9355.49 | G30: =G11-G29 -> 26253.38 | H30: =H11-H29 -> 9545.04 | I30: =I11-I29 -> 49310.41 | J30: =J11-J29 -> 27251.46 | K30: =K11-K29 -> 49659.98 | L30: =L11-L29 -> 3505 | ... AN30: =AN11-AN29 -> 392382.31
A32: Base Case | E32: Actual Budget | AC32: Forecast
B33: Account | E33: 45292 | F33: =EDATE(E$7,1) -> 45323 | G33: =EDATE(F$7,1) -> 45352 | H33: =EDATE(G$7,1) -> 45383 | I33: =EDATE(H$7,1) -> 45413 | J33: =EDATE(I$7,1) -> 45444 | K33: =EDATE(J$7,1) -> 45474 | L33: =EDATE(K$7,1) -> 45505 | M33: =EDATE(L$7,1) -> 45536 | ... AN33: =EDATE(AM$7,1) -> 46357
B34: Revenue
C35: Sales Revenue | E35: =SUMIFS( general_ledger!$E:$E, general_ledger!$F:$F,Forecast!$C35, general_ledger!$B:$B,">="&Forecast!E$7, general_ledger!$B:$B,"<"&EDATE(Forecast!E$7,1) ) -> 59415.49 | F35: =SUMIFS( general_ledger!$E:$E, general_ledger!$F:$F,Forecast!$C35, general_ledger!$B:$B,">="&Forecast!F$7, general_ledger!$B:$B,"<"&EDATE(Forecast!F$7,1) ) -> 68342.89 | G35: =SUMIFS( general_ledger!$E:$E, general_ledger!$F:$F,Forecast!$C35, general_ledger!$B:$B,">="&Forecast!G$7, general_ledger!$B:$B,"<"&EDATE(Forecast!G$7,1) ) -> 99595.54 | H35: =SUMIFS( general_ledger!$E:$E, general_ledger!$F:$F,Forecast!$C35, general_ledger!$B:$B,">="&Forecast!H$7, general_ledger!$B:$B,"<"&EDATE(Forecast!H$7,1) ) -> 95861.08 | I35: =SUMIFS( general_ledger!$E:$E, general_ledger!$F:$F,Forecast!$C35, general_ledger!$B:$B,">="&Forecast!I$7, general_ledger!$B:$B,"<"&EDATE(Forecast!I$7,1) ) -> 150362.92 | J35: =SUMIFS( general_ledger!$E:$E, general_ledger!$F:$F,Forecast!$C35, general_ledger!$B:$B,">="&Forecast!J$7, general_ledger!$B:$B,"<"&EDATE(Forecast!J$7,1) ) -> 142942.71 | K35: =SUMIFS( general_ledger!$E:$E, general_ledger!$F:$F,Forecast!$C35, general_ledger!$B:$B,">="&Forecast!K$7, general_ledger!$B:$B,"<"&EDATE(Forecast!K$7,1) ) -> 149964.53 | L35: =SUMIFS( general_ledger!$E:$E, general_ledger!$F:$F,Forecast!$C35, general_ledger!$B:$B,">="&Forecast!L$7, general_ledger!$B:$B,"<"&EDATE(Forecast!L$7,1) ) -> 134993.04 | ... AB35: =SUMIFS( general_ledger!$E:$E, general_ledger!$F:$F,Forecast!$C35, general_ledger!$B:$B,">="&Forecast!AB$7, general_ledger!$B:$B,"<"&EDATE(Forecast!AB$7,1) ) -> 511798.72 | AC35: =_xlfn.FORECAST.ETS(AC$7,$E35:AB35,$E$7:AB$7,) -> 335176.42 | AD35: =_xlfn.FORECAST.ETS(AD$7,$E35:AC35,$E$7:AC$7,) -> 318620.66 | AE35: =_xlfn.FORECAST.ETS(AE$7,$E35:AD35,$E$7:AD$7,) -> 350761.51 | AF35: =_xlfn.FORECAST.ETS(AF$7,$E35:AE35,$E$7:AE$7,) -> 380376.74 | AG35: =_xlfn.FORECAST.ETS(AG$7,$E35:AF35,$E$7:AF$7,) -> 454489.27 | AH35: =_xlfn.FORECAST.ETS(AH$7,$E35:AG35,$E$7:AG$7,) -> 451842.52 | AI35: =_xlfn.FORECAST.ETS(AI$7,$E35:AH35,$E$7:AH$7,) -> 393080.2 | AJ35: =_xlfn.FORECAST.ETS(AJ$7,$E35:AI35,$E$7:AI$7,) -> 375516.68 | ... AN35: =_xlfn.FORECAST.ETS(AN$7,$E35:AM35,$E$7:AM$7,) -> 519225.54
C36: Cost of Goods Sold | E36: =SUMIFS( general_ledger!$D:$D, general_ledger!$F:$F,Forecast!$C36, general_ledger!$B:$B,">="&Forecast!E$7, general_ledger!$B:$B,"<"&EDATE(Forecast!E$7,1) ) -> 17964.15 | F36: =SUMIFS( general_ledger!$D:$D, general_ledger!$F:$F,Forecast!$C36, general_ledger!$B:$B,">="&Forecast!F$7, general_ledger!$B:$B,"<"&EDATE(Forecast!F$7,1) ) -> 10317.94 | G36: =SUMIFS( general_ledger!$D:$D, general_ledger!$F:$F,Forecast!$C36, general_ledger!$B:$B,">="&Forecast!G$7, general_ledger!$B:$B,"<"&EDATE(Forecast!G$7,1) ) -> 28087.98 | H36: =SUMIFS( general_ledger!$D:$D, general_ledger!$F:$F,Forecast!$C36, general_ledger!$B:$B,">="&Forecast!H$7, general_ledger!$B:$B,"<"&EDATE(Forecast!H$7,1) ) -> 41028.11 | I36: =SUMIFS( general_ledger!$D:$D, general_ledger!$F:$F,Forecast!$C36, general_ledger!$B:$B,">="&Forecast!I$7, general_ledger!$B:$B,"<"&EDATE(Forecast!I$7,1) ) -> 56000.79 | J36: =SUMIFS( general_ledger!$D:$D, general_ledger!$F:$F,Forecast!$C36, general_ledger!$B:$B,">="&Forecast!J$7, general_ledger!$B:$B,"<"&EDATE(Forecast!J$7,1) ) -> 70351.5 | K36: =SUMIFS( general_ledger!$D:$D, general_ledger!$F:$F,Forecast!$C36, general_ledger!$B:$B,">="&Forecast!K$7, general_ledger!$B:$B,"<"&EDATE(Forecast!K$7,1) ) -> 53447.14 | L36: =SUMIFS( general_ledger!$D:$D, general_ledger!$F:$F,Forecast!$C36, general_ledger!$B:$B,">="&Forecast!L$7, general_ledger!$B:$B,"<"&EDATE(Forecast!L$7,1) ) -> 61886.94 | ... AB36: =SUMIFS( general_ledger!$D:$D, general_ledger!$F:$F,Forecast!$C36, general_ledger!$B:$B,">="&Forecast!AB$7, general_ledger!$B:$B,"<"&EDATE(Forecast!AB$7,1) ) -> 125511.47 | AC36: =_xlfn.FORECAST.ETS(AC$7,$E36:AB36,$E$7:AB$7,) -> 105559.39 | AD36: =_xlfn.FORECAST.ETS(AD$7,$E36:AC36,$E$7:AC$7,) -> 98215.521 | AE36: =_xlfn.FORECAST.ETS(AE$7,$E36:AD36,$E$7:AD$7,) -> 110236.53 | AF36: =_xlfn.FORECAST.ETS(AF$7,$E36:AE36,$E$7:AE$7,) -> 119319.65 | AG36: =_xlfn.FORECAST.ETS(AG$7,$E36:AF36,$E$7:AF$7,) -> 131209.26 | AH36: =_xlfn.FORECAST.ETS(AH$7,$E36:AG36,$E$7:AG$7,) -> 144512.17 | AI36: =_xlfn.FORECAST.ETS(AI$7,$E36:AH36,$E$7:AH$7,) -> 128471.18 | AJ36: =_xlfn.FORECAST.ETS(AJ$7,$E36:AI36,$E$7:AI$7,) -> 116105.5 | ... AN36: =_xlfn.FORECAST.ETS(AN$7,$E36:AM36,$E$7:AM$7,) -> 163605.46
B37: Gross Profit | E37: =E35-E36 -> 41451.34 | F37: =F35-F36 -> 58024.95 | G37: =G35-G36 -> 71507.56 | H37: =H35-H36 -> 54832.97 | I37: =I35-I36 -> 94362.13 | J37: =J35-J36 -> 72591.21 | K37: =K35-K36 -> 96517.39 | L37: =L35-L36 -> 73106.1 | ... AN37: =AN35-AN36 -> 355620.07
C38: Gross Profit Margin | E38: =E37/E35 -> 0.69765208 | F38: =F37/F35 -> 0.84902687 | G38: =G37/G35 -> 0.71797954 | H38: =H37/H35 -> 0.57200451 | I38: =I37/I35 -> 0.6275625 | J38: =J37/J35 -> 0.50783429 | K38: =K37/K35 -> 0.64360146 | L38: =L37/L35 -> 0.54155459 | ... AB38: =AB37/AB35 -> 0.754764 | AC38: =AVERAGE($E$12:$AB$12) -> 0.62557999 | AD38: =AVERAGE($E$12:$AB$12) -> 0.62557999 | AE38: =AVERAGE($E$12:$AB$12) -> 0.62557999 | AF38: =AVERAGE($E$12:$AB$12) -> 0.62557999 | AG38: =AVERAGE($E$12:$AB$12) -> 0.62557999 | AH38: =AVERAGE($E$12:$AB$12) -> 0.62557999 | AI38: =AVERAGE($E$12:$AB$12) -> 0.62557999 | AJ38: =AVERAGE($E$12:$AB$12) -> 0.62557999 | ... AN38: =AVERAGE($E$12:$AB$12) -> 0.62557999
B40: Operating Expense
C41: Depreciation Expense
D42: Depreciation â€” Counter & Checkout | E42: =SUMIFS( general_ledger!$D:$D, general_ledger!$C:$C,Forecast!$D42, general_ledger!$B:$B,">="&Forecast!E$7, general_ledger!$B:$B,"<"&EDATE(Forecast!E$7,1) ) -> 48.28 | F42: =SUMIFS( general_ledger!$D:$D, general_ledger!$C:$C,Forecast!$D42, general_ledger!$B:$B,">="&Forecast!F$7, general_ledger!$B:$B,"<"&EDATE(Forecast!F$7,1) ) -> 48.28 | G42: =SUMIFS( general_ledger!$D:$D, general_ledger!$C:$C,Forecast!$D42, general_ledger!$B:$B,">="&Forecast!G$7, general_ledger!$B:$B,"<"&EDATE(Forecast!G$7,1) ) -> 48.28 | H42: =SUMIFS( general_ledger!$D:$D, general_ledger!$C:$C,Forecast!$D42, general_ledger!$B:$B,">="&Forecast!H$7, general_ledger!$B:$B,"<"&EDATE(Forecast!H$7,1) ) -> 48.28 | I42: =SUMIFS( general_ledger!$D:$D, general_ledger!$C:$C,Forecast!$D42, general_ledger!$B:$B,">="&Forecast!I$7, general_ledger!$B:$B,"<"&EDATE(Forecast!I$7,1) ) -> 48.28 | J42: =SUMIFS( general_ledger!$D:$D, general_ledger!$C:$C,Forecast!$D42, general_ledger!$B:$B,">="&Forecast!J$7, general_ledger!$B:$B,"<"&EDATE(Forecast!J$7,1) ) -> 48.28 | K42: =SUMIFS( general_ledger!$D:$D, general_ledger!$C:$C,Forecast!$D42, general_ledger!$B:$B,">="&Forecast!K$7, general_ledger!$B:$B,"<"&EDATE(Forecast!K$7,1) ) -> 48.28 | L42: =SUMIFS( general_ledger!$D:$D, general_ledger!$C:$C,Forecast!$D42, general_ledger!$B:$B,">="&Forecast!L$7, general_ledger!$B:$B,"<"&EDATE(Forecast!L$7,1) ) -> 48.28 | ... AB42: =SUMIFS( general_ledger!$D:$D, general_ledger!$C:$C,Forecast!$D42, general_ledger!$B:$B,">="&Forecast!AB$7, general_ledger!$B:$B,"<"&EDATE(Forecast!AB$7,1) ) -> 48.28
D43: Depreciation â€” Delivery Van | E43: =SUMIFS( general_ledger!$D:$D, general_ledger!$C:$C,Forecast!$D43, general_ledger!$B:$B,">="&Forecast!E$7, general_ledger!$B:$B,"<"&EDATE(Forecast!E$7,1) ) -> 232.19 | F43: =SUMIFS( general_ledger!$D:$D, general_ledger!$C:$C,Forecast!$D43, general_ledger!$B:$B,">="&Forecast!F$7, general_ledger!$B:$B,"<"&EDATE(Forecast!F$7,1) ) -> 232.19 | G43: =SUMIFS( general_ledger!$D:$D, general_ledger!$C:$C,Forecast!$D43, general_ledger!$B:$B,">="&Forecast!G$7, general_ledger!$B:$B,"<"&EDATE(Forecast!G$7,1) ) -> 232.19 | H43: =SUMIFS( general_ledger!$D:$D, general_ledger!$C:$C,Forecast!$D43, general_ledger!$B:$B,">="&Forecast!H$7, general_ledger!$B:$B,"<"&EDATE(Forecast!H$7,1) ) -> 232.19 | I43: =SUMIFS( general_ledger!$D:$D, general_ledger!$C:$C,Forecast!$D43, general_ledger!$B:$B,">="&Forecast!I$7, general_ledger!$B:$B,"<"&EDATE(Forecast!I$7,1) ) -> 232.19 | J43: =SUMIFS( general_ledger!$D:$D, general_ledger!$C:$C,Forecast!$D43, general_ledger!$B:$B,">="&Forecast!J$7, general_ledger!$B:$B,"<"&EDATE(Forecast!J$7,1) ) -> 232.19 | K43: =SUMIFS( general_ledger!$D:$D, general_ledger!$C:$C,Forecast!$D43, general_ledger!$B:$B,">="&Forecast!K$7, general_ledger!$B:$B,"<"&EDATE(Forecast!K$7,1) ) -> 232.19 | L43: =SUMIFS( general_ledger!$D:$D, general_ledger!$C:$C,Forecast!$D43, general_ledger!$B:$B,">="&Forecast!L$7, general_ledger!$B:$B,"<"&EDATE(Forecast!L$7,1) ) -> 232.19 | ... AB43: =SUMIFS( general_ledger!$D:$D, general_ledger!$C:$C,Forecast!$D43, general_ledger!$B:$B,">="&Forecast!AB$7, general_ledger!$B:$B,"<"&EDATE(Forecast!AB$7,1) ) -> 232.19
D44: Depreciation â€” Display Stands | E44: =SUMIFS( general_ledger!$D:$D, general_ledger!$C:$C,Forecast!$D44, general_ledger!$B:$B,">="&Forecast!E$7, general_ledger!$B:$B,"<"&EDATE(Forecast!E$7,1) ) -> 76.8 | F44: =SUMIFS( general_ledger!$D:$D, general_ledger!$C:$C,Forecast!$D44, general_ledger!$B:$B,">="&Forecast!F$7, general_ledger!$B:$B,"<"&EDATE(Forecast!F$7,1) ) -> 76.8 | G44: =SUMIFS( general_ledger!$D:$D, general_ledger!$C:$C,Forecast!$D44, general_ledger!$B:$B,">="&Forecast!G$7, general_ledger!$B:$B,"<"&EDATE(Forecast!G$7,1) ) -> 76.8 | H44: =SUMIFS( general_ledger!$D:$D, general_ledger!$C:$C,Forecast!$D44, general_ledger!$B:$B,">="&Forecast!H$7, general_ledger!$B:$B,"<"&EDATE(Forecast!H$7,1) ) -> 76.8 | I44: =SUMIFS( general_ledger!$D:$D, general_ledger!$C:$C,Forecast!$D44, general_ledger!$B:$B,">="&Forecast!I$7, general_ledger!$B:$B,"<"&EDATE(Forecast!I$7,1) ) -> 76.8 | J44: =SUMIFS( general_ledger!$D:$D, general_ledger!$C:$C,Forecast!$D44, general_ledger!$B:$B,">="&Forecast!J$7, general_ledger!$B:$B,"<"&EDATE(Forecast!J$7,1) ) -> 76.8 | K44: =SUMIFS( general_ledger!$D:$D, general_ledger!$C:$C,Forecast!$D44, general_ledger!$B:$B,">="&Forecast!K$7, general_ledger!$B:$B,"<"&EDATE(Forecast!K$7,1) ) -> 76.8 | L44: =SUMIFS( general_ledger!$D:$D, general_ledger!$C:$C,Forecast!$D44, general_ledger!$B:$B,">="&Forecast!L$7, general_ledger!$B:$B,"<"&EDATE(Forecast!L$7,1) ) -> 76.8 | ... AB44: =SUMIFS( general_ledger!$D:$D, general_ledger!$C:$C,Forecast!$D44, general_ledger!$B:$B,">="&Forecast!AB$7, general_ledger!$B:$B,"<"&EDATE(Forecast!AB$7,1) ) -> 76.8
D45: Depreciation â€” Laptop x2 | E45: =SUMIFS( general_ledger!$D:$D, general_ledger!$C:$C,Forecast!$D45, general_ledger!$B:$B,">="&Forecast!E$7, general_ledger!$B:$B,"<"&EDATE(Forecast!E$7,1) ) -> 76.86 | F45: =SUMIFS( general_ledger!$D:$D, general_ledger!$C:$C,Forecast!$D45, general_ledger!$B:$B,">="&Forecast!F$7, general_ledger!$B:$B,"<"&EDATE(Forecast!F$7,1) ) -> 76.86 | G45: =SUMIFS( general_ledger!$D:$D, general_ledger!$C:$C,Forecast!$D45, general_ledger!$B:$B,">="&Forecast!G$7, general_ledger!$B:$B,"<"&EDATE(Forecast!G$7,1) ) -> 76.86 | H45: =SUMIFS( general_ledger!$D:$D, general_ledger!$C:$C,Forecast!$D45, general_ledger!$B:$B,">="&Forecast!H$7, general_ledger!$B:$B,"<"&EDATE(Forecast!H$7,1) ) -> 76.86 | I45: =SUMIFS( general_ledger!$D:$D, general_ledger!$C:$C,Forecast!$D45, general_ledger!$B:$B,">="&Forecast!I$7, general_ledger!$B:$B,"<"&EDATE(Forecast!I$7,1) ) -> 76.86 | J45: =SUMIFS( general_ledger!$D:$D, general_ledger!$C:$C,Forecast!$D45, general_ledger!$B:$B,">="&Forecast!J$7, general_ledger!$B:$B,"<"&EDATE(Forecast!J$7,1) ) -> 76.86 | K45: =SUMIFS( general_ledger!$D:$D, general_ledger!$C:$C,Forecast!$D45, general_ledger!$B:$B,">="&Forecast!K$7, general_ledger!$B:$B,"<"&EDATE(Forecast!K$7,1) ) -> 76.86 | L45: =SUMIFS( general_ledger!$D:$D, general_ledger!$C:$C,Forecast!$D45, general_ledger!$B:$B,">="&Forecast!L$7, general_ledger!$B:$B,"<"&EDATE(Forecast!L$7,1) ) -> 76.86 | ... AB45: =SUMIFS( general_ledger!$D:$D, general_ledger!$C:$C,Forecast!$D45, general_ledger!$B:$B,">="&Forecast!AB$7, general_ledger!$B:$B,"<"&EDATE(Forecast!AB$7,1) ) -> 0
...

Sheet Chart
A1: Sales Revenue | B1: 45292 | C1: =EDATE(B$1,1) -> 45323 | D1: =EDATE(C$1,1) -> 45352 | E1: =EDATE(D$1,1) -> 45383 | F1: =EDATE(E$1,1) -> 45413 | G1: =EDATE(F$1,1) -> 45444 | H1: =EDATE(G$1,1) -> 45474 | I1: =EDATE(H$1,1) -> 45505 | J1: =EDATE(I$1,1) -> 45536 | ... AK1: =EDATE(AJ$1,1) -> 46357
A2: Base Case | B2: 59415.49 | C2: 68342.89 | D2: 99595.54 | E2: 95861.08 | F2: 150362.92 | G2: 142942.71 | H2: 149964.53 | I2: 134993.04 | J2: 141063.74 | K2: 205049.57 | L2: 232928.63 | M2: 309332.22 | N2: 153642.58 | O2: 138235.13 | P2: 177988.44 | Q2: 217996.4 | R2: 329150.24 | S2: 242501.94 | T2: 216498.92 | U2: 191254.52 | V2: 317274.78 | W2: 299056.04 | X2: 403762.46 | Y2: 511798.72 | Z2: 335176.42 | AA2: 318620.66 | AB2: 350761.51 | AC2: 380376.74 | AD2: 454489.27 | AE2: 451842.52 | AF2: 393080.2 | AG2: 375516.68 | AH2: 425519.69 | AI2: 454340.2 | AJ2: 526005.78 | AK2: 519225.54
A3: Best Case | B3: 59415.49 | C3: 68342.89 | D3: 99595.54 | E3: 95861.08 | F3: 150362.92 | G3: 142942.71 | H3: 149964.53 | I3: 134993.04 | J3: 141063.74 | K3: 205049.57 | L3: 232928.63 | M3: 309332.22 | N3: 153642.58 | O3: 138235.13 | P3: 177988.44 | Q3: 217996.4 | R3: 329150.24 | S3: 242501.94 | T3: 216498.92 | U3: 191254.52 | V3: 317274.78 | W3: 299056.04 | X3: 403762.46 | Y3: 511798.72 | Z3: 435729.35 | AA3: 414206.86 | AB3: 455989.96 | AC3: 494489.76 | AD3: 590836.05 | AE3: 587395.28 | AF3: 511004.26 | AG3: 488171.68 | AH3: 553175.6 | AI3: 590642.26 | AJ3: 683807.52 | AK3: 674993.2
A4: Worst Case | B4: 59415.49 | C4: 68342.89 | D4: 99595.54 | E4: 95861.08 | F4: 150362.92 | G4: 142942.71 | H4: 149964.53 | I4: 134993.04 | J4: 141063.74 | K4: 205049.57 | L4: 232928.63 | M4: 309332.22 | N4: 153642.58 | O4: 138235.13 | P4: 177988.44 | Q4: 217996.4 | R4: 329150.24 | S4: 242501.94 | T4: 216498.92 | U4: 191254.52 | V4: 317274.78 | W4: 299056.04 | X4: 403762.46 | Y4: 511798.72 | Z4: 234623.49 | AA4: 223034.47 | AB4: 245533.06 | AC4: 266263.72 | AD4: 318142.49 | AE4: 316289.77 | AF4: 275156.14 | AG4: 262861.67 | AH4: 297863.78 | AI4: 318038.14 | AJ4: 368204.05 | AK4: 363457.88
A6: Date | B6: 45292 | C6: =EDATE(B$1,1) -> 45323 | D6: =EDATE(C$1,1) -> 45352 | E6: =EDATE(D$1,1) -> 45383 | F6: =EDATE(E$1,1) -> 45413 | G6: =EDATE(F$1,1) -> 45444 | H6: =EDATE(G$1,1) -> 45474 | I6: =EDATE(H$1,1) -> 45505 | J6: =EDATE(I$1,1) -> 45536 | ... AK6: =EDATE(AJ$1,1) -> 46357
A7: Sales Revenue | B7: 59415.49 | C7: 68342.89 | D7: 99595.54 | E7: 95861.08 | F7: 150362.92 | G7: 142942.71 | H7: 149964.53 | I7: 134993.04 | J7: 141063.74 | K7: 205049.57 | L7: 232928.63 | M7: 309332.22 | N7: 153642.58 | O7: 138235.13 | P7: 177988.44 | Q7: 217996.4 | R7: 329150.24 | S7: 242501.94 | T7: 216498.92 | U7: 191254.52 | V7: 317274.78 | W7: 299056.04 | X7: 403762.46 | Y7: 511798.72 | Z7: 335176.42 | AA7: 318620.66 | AB7: 350761.51 | AC7: 380376.74 | AD7: 454489.27 | AE7: 451842.52 | AF7: 393080.2 | AG7: 375516.68 | AH7: 425519.69 | AI7: 454340.2 | AJ7: 526005.78 | AK7: 519225.54
A8: Gross Profit | B8: 41451.34 | C8: 58024.95 | D8: 71507.56 | E8: 54832.97 | F8: 94362.13 | G8: 72591.21 | H8: 96517.39 | I8: 73106.1 | J8: 69372.78 | K8: 142291.13 | L8: 139263.91 | M8: 202576.19 | N8: 76939.69 | O8: 85224.69 | P8: 103852.16 | Q8: 111218.43 | R8: 237815.49 | S8: 138667.89 | T8: 113578.87 | U8: 111754.24 | V8: 215849.4 | W8: 195535.28 | X8: 288716.93 | Y8: 386287.25 | Z8: 229617.03 | AA8: 220405.14 | AB8: 240524.98 | AC8: 261057.08 | AD8: 323280.01 | AE8: 307330.35 | AF8: 264609.02 | AG8: 259411.18 | AH8: 297203.39 | AI8: 314465.76 | AJ8: 375754.73 | AK8: 355620.07
A9: Operational Profit | B9: -3753.37 | C9: -9355.49 | D9: 26253.38 | E9: 9545.04 | F9: 49310.41 | G9: 27251.46 | H9: 49659.98 | I9: 3505 | J9: 22802.56 | K9: 95283.58 | L9: 92693.69 | M9: 155744.97 | N9: 6784.2 | O9: 38654.47 | P9: 57281.94 | Q9: 64648.21 | R9: 190089.86 | S9: 91623.59 | T9: 40982.93 | U9: 66149.38 | V9: 168106.31 | W9: 147970.56 | X9: 241206.87 | Y9: 338786.93 | Z9: 169197.49 | AA9: 160396.09 | AB9: 192078.31 | AC9: 213450.61 | AD9: 274472.33 | AE9: 258803.57 | AF9: 198776.39 | AG9: 202754.98 | AH9: 247550.92 | AI9: 265594.1 | AJ9: 325659.93 | AK9: 305490.34
